<?xml version="1.0"?>
<!-- Revolute-Revolute Manipulator -->
<robot name="rrbot" xmlns:xacro="http://www.ros.org/wiki/xacro">

  <!-- Constants for robot dimensions -->
  <xacro:property name="PI" value="3.1415926535897931"/>
  <xacro:property name="mass" value="1" /> <!-- arbitrary value for mass -->
  <xacro:property name="width" value="0.1" /> <!-- Square dimensions (widthxwidth) of beams -->
  <xacro:property name="height1" value="2" /> <!-- Link 1 -->
  <xacro:property name="height2" value="1" /> <!-- Link 2 -->
  <xacro:property name="height3" value="1" /> <!-- Link 3 -->
  <xacro:property name="camera_link" value="0.05" /> <!-- Size of square 'camera' box -->
  <xacro:property name="axel_offset" value="0.05" /> <!-- Space btw top of beam and the each joint -->

  <!-- Import all Gazebo-customization elements, including Gazebo colors -->
  <xacro:include filename="$(find rrbot_description)/urdf/rrbot.gazebo" />
  <!-- Import Rviz colors -->
  <xacro:include filename="$(find rrbot_description)/urdf/materials.xacro" />

  <!-- Used for fixing robot to Gazebo 'base_link' -->
  <link name="world"/>

  <joint name="fixed" type="fixed">
    <parent link="world"/>
    <child link="link1"/>
  </joint>

  <!-- Base Link -->
  <link name="link1">
    <collision>
      <origin xyz="0 0 1" rpy="0 0 0"/>
      <geometry>
	<box size="0.1 0.1 2"/>
      </geometry>
    </collision>

    <visual>
      <origin xyz="0 0 1" rpy="0 0 0"/>
      <geometry>
	<box size="0.1 0.1 2"/>
      </geometry>
      <material name="orange"/>
    </visual>

    <inertial>
      <origin xyz="0 0 1" rpy="0 0 0"/>
      <mass value="1"/>
      <inertia
	  ixx="0.334" ixy="0.0" ixz="0.0"
	  iyy="0.334" iyz="0.0"
	  izz="0.0016"/>
    </inertial>
  </link>

  <joint name="joint1" type="continuous">
    <parent link="link1"/>
    <child link="link2"/>
    <origin xyz="0 0.1 1.95" rpy="0 0 0"/>
    <axis xyz="0 1 0"/>
    <dynamics damping="0.7"/>
  </joint>

  <!-- Middle Link -->
  <link name="link2">
    <collision>
      <origin xyz="0 0 0.45" rpy="0 0 0"/>
      <geometry>
	<box size="0.1 0.1 1"/>
      </geometry>
    </collision>

    <visual>
      <origin xyz="0 0 0.45" rpy="0 0 0"/>
      <geometry>
	<box size="0.1 0.1 1"/>
      </geometry>
      <material name="black"/>
    </visual>

    <inertial>
      <origin xyz="0 0 0.45" rpy="0 0 0"/>
      <mass value="1"/>
      <inertia
	  ixx="0.084" ixy="0.0" ixz="0.0"
	  iyy="0.084" iyz="0.0"
	  izz="0.016"/>
    </inertial>
  </link>

  <joint name="joint2" type="continuous">
    <parent link="link2"/>
    <child link="link3"/>
    <origin xyz="0 0.1 0.9" rpy="0 0 0"/>
    <axis xyz="0 1 0"/>
    <dynamics damping="0.7"/>
  </joint>

  <!-- Top Link -->
  <link name="link3">
    <collision>
      <origin xyz="0 0 0.45" rpy="0 0 0"/>
      <geometry>
	<box size="0.1 0.1 1"/>
      </geometry>
    </collision>

    <visual>
      <origin xyz="0 0 0.45" rpy="0 0 0"/>
      <geometry>
	<box size="0.1 0.1 1"/>
      </geometry>
      <material name="orange"/>
    </visual>

    <inertial>
      <origin xyz="0 0 0.45" rpy="0 0 0"/>
      <mass value="1"/>
      <inertia
	  ixx="0.084" ixy="0.0" ixz="0.0"
	  iyy="0.084" iyz="0.0"
	  izz="0.016"/>
    </inertial>
  </link>

  <joint name="hokuyo_joint" type="fixed">
    <axis xyz="0 1 0" />
    <origin xyz="0 0 0.95" rpy="0 0 0"/>
    <parent link="link3"/>
    <child link="hokuyo_link"/>
  </joint>

  <!-- Hokuyo Laser -->
  <link name="hokuyo_link">
    <collision>
      <origin xyz="0 0 0" rpy="0 0 0"/>
      <geometry>
	<box size="0.1 0.1 0.1"/>
      </geometry>
    </collision>

    <visual>
      <origin xyz="0 0 0" rpy="0 0 0"/>
      <geometry>
        <mesh filename="package://rrbot_description/meshes/hokuyo.dae"/>
      </geometry>
    </visual>

    <inertial>
      <mass value="1e-5" />
      <origin xyz="0 0 0" rpy="0 0 0"/>
      <inertia ixx="1e-6" ixy="0" ixz="0" iyy="1e-6" iyz="0" izz="1e-6" />
    </inertial>
  </link>

  <joint name="camera_joint" type="fixed">
    <axis xyz="0 1 0" />
    <origin xyz="0.05 0 0.9" rpy="0 0 0"/>
    <parent link="link3"/>
    <child link="camera_link"/>
  </joint>

  <!-- Camera -->
  <link name="camera_link">
    <collision>
      <origin xyz="0 0 0" rpy="0 0 0"/>
      <geometry>
	<box size="0.05 0.05 0.05"/>
      </geometry>
    </collision>

    <visual>
      <origin xyz="0 0 0" rpy="0 0 0"/>
      <geometry>
	<box size="0.05 0.05 0.05"/>
      </geometry>
      <material name="red"/>
    </visual>

    <inertial>
      <mass value="1e-5" />
      <origin xyz="0 0 0" rpy="0 0 0"/>
      <inertia ixx="1e-6" ixy="0" ixz="0" iyy="1e-6" iyz="0" izz="1e-6" />
    </inertial>
  </link>

  <!-- generate an optical frame http://www.ros.org/reps/rep-0103.html#suffix-frames
      so that ros and opencv can operate on the camera frame correctly -->
  <joint name="camera_optical_joint" type="fixed">
    <!-- these values have to be these values otherwise the gazebo camera image
        won't be aligned properly with the frame it is supposedly originating from -->
    <origin xyz="0 0 0" rpy="-1.57 0 -1.57"/>
    <parent link="camera_link"/>
    <child link="camera_link_optical"/>
  </joint>

  <link name="camera_link_optical">
  </link>

  <transmission name="tran1">
    <type>transmission_interface/SimpleTransmission</type>
    <joint name="joint1">
      <hardwareInterface>hardware_interface/EffortJointInterface</hardwareInterface>
    </joint>
    <actuator name="motor1">
      <hardwareInterface>hardware_interface/EffortJointInterface</hardwareInterface>
      <mechanicalReduction>1</mechanicalReduction>
    </actuator>
  </transmission>

  <transmission name="tran2">
    <type>transmission_interface/SimpleTransmission</type>
    <joint name="joint2">
      <hardwareInterface>hardware_interface/EffortJointInterface</hardwareInterface>
    </joint>
    <actuator name="motor2">
      <hardwareInterface>hardware_interface/EffortJointInterface</hardwareInterface>
      <mechanicalReduction>1</mechanicalReduction>
    </actuator>
  </transmission>

</robot>