<mujoco>
    <worldbody>
        <geom name="ROMERIN" type="box" size="0.08 0.0825 0.035" rgba="1 1 1 1"/>
        <body name="THOR" pos="0.08 0.0825 0" euler="0 0 45.8814">
            <geom name="colision_b0" type="capsule" size="0.025 0.008" euler="0 90 0" rgba="1 1 1 0.2"/>
            <body name="link_1" pos="0.069 0 0" >
                <inertial pos="0 0 0" mass="0.212" diaginertia="1 1 1"/>
                <geom name="colision_b1" type="sphere" size="0.032" euler="0 90 0" rgba="1 1 1 0.2"/>
                <site name="mass_b1" type="box" size="0.0038 0.0038 0.0038"  euler="0 90 0" rgba="1 0 0 1"/>
                <site name="sensor_b1" pos="-0.034 0 0"/>
                <joint name="Q1" type="hinge" pos="-0.034 0 0" axis="0 0 1" limited="true" range="-110 110" stiffness="1" damping="1" frictionloss="0.5"/>
                <body name="link_2" pos="0.034 0 0">
                    <inertial pos="0.118 0 -0.00745" mass="0.360" diaginertia="1 1 1"/>
                    <geom name="colision_b2" type="capsule" size="0.032" fromto="0.034 0 0 0.202 0 -0.0129" rgba="1 1 1 0.2"/>
                    <site name="sensor_b2" pos="0 0 0"/>
                    <site name="mass_b2" type="box" size="0.0038 0.0038 0.0038"  euler="0 90 0" rgba="1 0 0 1"/>
                    <joint name="Q2" type="hinge" pos="0 0 0" axis="0 -1 0" limited="true" range="-110 110"  stiffness="1" damping="1" frictionloss="0.5"/>
                    <body name="link_3" pos="0.236 0 -0.0149">
                        <inertial pos="0.14 0 0.011" mass="0.535" diaginertia="1 1 1"/>
                        <geom name="colision_b3" type="capsule" size="0.032" fromto="0.034 0 0 0.199 0 0.02" rgba="1 1 1 0.2"/>
                        <site name="sensor_b3" pos="0 0 0"/>
                        <site name="mass_b3" type="box" size="0.0038 0.0038 0.0038"  euler="0 90 0" rgba="1 0 0 1"/>
                        <joint name="Q3" type="hinge" pos="0 0 0" axis="0 1 -0" limited="true" range="-35 170"  stiffness="1" damping="1" frictionloss="0.5"/>
                        <body name="link_4" pos="0.28 0 0.022">
                            <inertial pos="0 0 0" mass="0.205" diaginertia="1 1 1"/>
                            <geom name="colision_b4" type="sphere" size="0.035" rgba="1 1 1 0.2"/>
                            <site name="sensor_b4" pos="-0.28 0 0"/>
                            <site name="mass_b4" type="box" size="0.0038 0.0038 0.0038"  euler="0 90 0" rgba="1 0 0 1"/>
                            <joint name="Q4" type="hinge" pos="-0.28 0 0" axis="-1 0 0" limited="true" range="-180 180"  stiffness="1" damping="1" frictionloss="0.5"/>
                            <body name="link_5" pos="0 0 0">
                                <inertial pos="0 0 0" mass="0.125" diaginertia="1 1 1"/>
                                <geom name="nolink_5" type="sphere" size="0.001" euler="0 90 0" rgba="1 1 1 0.2"/>
                                <site name="sensor_b5" pos="0 0 0"/>
                                <site name="mass_b5" type="box" size="0.0038 0.0038 0.0038"  euler="0 90 0" rgba="1 0 0 1"/>
                                <joint name="Q5" type="hinge" pos="0 0 0" axis="0 -1 0" limited="true" range="-180 180"  stiffness="1" damping="1" frictionloss="0.5"/>
                                <body name="link_6" pos="0.087 0 0">
                                    <inertial pos="0 0 0" mass="0.287" diaginertia="1 1 1"/>
                                    <geom name="colision_b6_up" type="cylinder" size="0.047 0.0185" pos="-0.0295 0 0" euler="0 90 0" rgba="1 1 1 0.2"/>
                                    <geom name="colision_b6_contact" type="cylinder" size="0.095 0.011" euler="0 90 0" rgba="1 1 1 0.2"/>
                                    
                                    <site name="sensor_b6" pos="-0.087 0 0"/>
                                    <site name="mass_b6" type="box" size="0.0038 0.0038 0.0038"  euler="0 90 0" rgba="1 0 0 1"/>
                                                            
                                    <joint name="Q6" type="hinge" pos="-0.087 0 0" axis="1 0 -0" limited="true" range="-180 180"  stiffness="1" damping="1" frictionloss="0.5"/>
                                    <body name="adhesion_contact" pos="0.011 0 0">
                                        <geom name="contact" type="cylinder" size="0.09 0.0005" pos="0.0005 0 0" euler="0 90 0" rgba="5 5 5 0"/>

                                        <!-- <site name="prx_1" pos="0.0001 0.022 0.0381" euler="0 90 0"/>
                                        <site name="prx_2" pos="0.0001 -0.044 0" euler="0 90 0"/>
                                        <site name="prx_3" pos="0.0001 0.022 -0.0381" euler="0 90 0"/>
                                        <site name="prss" type="cylinder" size="0.095 0.0005" pos="0.002 0 0" euler="0 90 0" rgba="10 1 1 0"/> -->
                                    </body>
                                </body>
                            </body>
                        </body>
                    </body>
                </body>
            </body>
        </body>
    </worldbody>
</mujoco>