<mujoco>
   <worldbody>
        <geom name="mastil" type="box" size="0.1 0.1 0.8" rgba="5 1 1 1"/>
        <body name="brazo" pos="0 0 0.8">
            <inertial pos="0 0 0.4" mass="1" diaginertia="1 1 1"/>
            <geom name="brazo" type="box" size="0.02 0.02 0.4" pos="0 0 0.4" rgba="5 1 1 1" contype="2" conaffinity="2"/>
            <joint name="articulacion" type="hinge" axis="0 1 0" damping="0.5" frictionloss="0"/>
        </body>
    </worldbody>

    <actuator>
        <motor name="motor" joint="articulacion" ctrllimited="true" ctrlrange="-3.92 3.92"/>
    </actuator>
</mujoco>